Workbook

Sheet 00_Executive_Summary
A1: Project Overview
A3: Built a fully integrated 36-month operating model for a high-growth multi-product fintech (payments, subscription, and lending), incorporating unit economics, capital planning, venture debt, and valuation sensitivity.
A4: The model links operating drivers (acquisition, churn, CAC, lending penetration) to 3-statement outputs, funding strategy, and ownership dilution outcomes.
A6: Base Scenario — 36-Month Outlook
A7: Revenue (Y3): 29.3m
A8: ARR (M36): 21.2m
A9: Gross Margin: 81%
A10: EBITDA Margin (Y3): -51.3%
A11: LTV/CAC (M12): 5.31
A12: Burn Multiple (M12): 26.8
A14: Lending activates Month 9 (scenario-dependent).
A15: 4m venture debt facility (10% annual) integrated into funding structure.
... A31: The model demonstrates the structural capital intensity of early-stage fintech expansion under realistic cost assumptions.

Sheet 01_Dashboard
A1: Revenue (Y3) | E1: ARR (M36) | I1: EBITDA Margin % (Y3) | M1: LTV/CAC (M12) | Q1: Burn Multiple (M12) | U1: Dilution %
A2: ='10_Income_Statement'!AN3 -> 29279351 | E2: ='03_KPIs'!AK4 -> 21203585 | I2: ='03_KPIs'!AN10 -> -0.51265641 | M2: ='03_KPIs'!AL8 -> 5.3056619 | Q2: ='03_KPIs'!AL12 -> 26.802941 | U2: ='02_Valuation'!B13 -> 0.74411549
A18: Unit Economics | M18: Capital Strategy | S18: Sensitivity Summary
A20: CAC | C20: ='32_Inputs_GrowthRetention'!$D$15 -> 110 | M20: Raise Month | N20: Pre - Money Equity Value | O20: Raise Size | P20: Post - Money Equity Value | Q20: Dilution % | R20: Net Debt (M36) | S20: Scenario | T20: ARR M36 | V20: EBITDA Margin M36 | X20: Dilution
S21: Downside | T21: 11053772 | V21: -1.3736224 | X21: 0.76647181
A22: Lifetime Value | C22: ='03_KPIs'!AN6 -> 564.76427 | M22: ='20_Capital_Sensitivity'!H2 -> 6 | N22: ='02_Valuation'!B10 -> 8596935.4 | O22: ='20_Capital_Sensitivity'!I2 -> 25000000 | P22: ='02_Valuation'!B11 -> 33596935 | Q22: ='02_Valuation'!B13 -> 0.74411549 | R22: ='03_KPIs'!AN14 -> 34289184 | S22: Base | T22: 21203585 | V22: -0.51265641 | X22: 0.74411549
S23: Upside | T23: 26280797 | V23: -0.19561799 | X23: 0.73111086
A24: CAC Payback (Months) | C24: ='03_KPIs'!AN7 -> 4.6694449 | S24: Scenario
S25: Base
A26: Gross Profit Margin | C26: ='03_KPIs'!AN9 -> 0.81419302

Sheet 02_Valuation
A1: Assumptions
A2: ARR Multiple (Base) | B2: 8
A3: Revenue Multiple (Base) | B3: 5
A4: Target Raise Month | B4: ='21_Scenarios'!$G$2 -> 6
A5: Raise Amount | B5: ='21_Scenarios'!$H$2 -> 25000000
A7: ARR before Raise | B7: {=INDEX('03_KPIs'!B4:AK4,'02_Valuation'!B4-1)} -> 1346120.3
A8: Enterprise Value | B8: =B7*B2 -> 10768962
A9: Net Debt before Raise | B9: {=INDEX('03_KPIs'!B14:AK14,'02_Valuation'!B4-1)} -> 2172026.9
A10: Equity Value | B10: =B8-B9 -> 8596935.4
A11: Post Money Valuation | B11: =B10+B5 -> 33596935
A13: Dilution % | B13: =B5/B11 -> 0.74411549
A14: Existing Ownership % | B14: =B10/B11 -> 0.25588451

Sheet 03_KPIs
A1: {='23_Time'!A1:AK2} -> Month Index | B1: 1 | C1: 2 | D1: 3 | E1: 4 | F1: 5 | G1: 6 | H1: 7 | I1: 8 | J1: 9 | K1: 10 | L1: 11 | M1: 12 | N1: 13 | O1: 14 | P1: 15 | Q1: 16 | R1: 17 | S1: 18 | T1: 19 | U1: 20 | V1: 21 | W1: 22 | X1: 23 | Y1: 24 | Z1: 25 | AA1: 26 | AB1: 27 | AC1: 28 | AD1: 29 | AE1: 30 | AF1: 31 | AG1: 32 | AH1: 33 | AI1: 34 | AJ1: 35 | AK1: 36
A2: Month Label | B2: M1 | C2: M2 | D2: M3 | E2: M4 | F2: M5 | G2: M6 | H2: M7 | I2: M8 | J2: M9 | K2: M10 | L2: M11 | M2: M12 | N2: M13 | O2: M14 | P2: M15 | Q2: M16 | R2: M17 | S2: M18 | T2: M19 | U2: M20 | V2: M21 | W2: M22 | X2: M23 | Y2: M24 | Z2: M25 | AA2: M26 | AB2: M27 | AC2: M28 | AD2: M29 | AE2: M30 | AF2: M31 | AG2: M32 | AH2: M33 | AI2: M34 | AJ2: M35 | AK2: M36 | AL2: Y1 Total | AM2: Y2 Total | AN2: Y3 Total
A3: Monthly Revenue Growth | B3: 0 | C3: =('41_Revenue_COGS'!C18/'41_Revenue_COGS'!B18)-1 -> 1.025105 | D3: =('41_Revenue_COGS'!D18/'41_Revenue_COGS'!C18)-1 -> 0.51994043 | E3: =('41_Revenue_COGS'!E18/'41_Revenue_COGS'!D18)-1 -> 0.35204487 | F3: =('41_Revenue_COGS'!F18/'41_Revenue_COGS'!E18)-1 -> 0.26846495 | G3: =('41_Revenue_COGS'!G18/'41_Revenue_COGS'!F18)-1 -> 0.21860948 | H3: =('41_Revenue_COGS'!H18/'41_Revenue_COGS'!G18)-1 -> 0.18561432 | I3: =('41_Revenue_COGS'!I18/'41_Revenue_COGS'!H18)-1 -> 0.16225164 | J3: =('41_Revenue_COGS'!J18/'41_Revenue_COGS'!I18)-1 -> 0.16060671 | ... AK3: =('41_Revenue_COGS'!AK18/'41_Revenue_COGS'!AJ18)-1 -> 0.045253532 | AM3: =('41_Revenue_COGS'!AM18/'41_Revenue_COGS'!AL18)-1 -> 2.665729 | AN3: =('41_Revenue_COGS'!AN18/'41_Revenue_COGS'!AM18)-1 -> 1.2856295
A4: Annual Recuring Revenue | B4: =('41_Revenue_COGS'!B10+'41_Revenue_COGS'!B8+'41_Revenue_COGS'!B17)*12 -> 255000 | C4: =('41_Revenue_COGS'!C10+'41_Revenue_COGS'!C8+'41_Revenue_COGS'!C17)*12 -> 516401.77 | D4: =('41_Revenue_COGS'!D10+'41_Revenue_COGS'!D8+'41_Revenue_COGS'!D17)*12 -> 784899.94 | E4: =('41_Revenue_COGS'!E10+'41_Revenue_COGS'!E8+'41_Revenue_COGS'!E17)*12 -> 1061219.9 | F4: =('41_Revenue_COGS'!F10+'41_Revenue_COGS'!F8+'41_Revenue_COGS'!F17)*12 -> 1346120.3 | G4: =('41_Revenue_COGS'!G10+'41_Revenue_COGS'!G8+'41_Revenue_COGS'!G17)*12 -> 1640394.9 | H4: =('41_Revenue_COGS'!H10+'41_Revenue_COGS'!H8+'41_Revenue_COGS'!H17)*12 -> 1944875.7 | I4: =('41_Revenue_COGS'!I10+'41_Revenue_COGS'!I8+'41_Revenue_COGS'!I17)*12 -> 2260435 | ... AK4: =('41_Revenue_COGS'!AK10+'41_Revenue_COGS'!AK8+'41_Revenue_COGS'!AK17)*12 -> 21203585 | AL4: =M4 -> 3728742.7 | AM4: =Y4 -> 10187387 | AN4: =AK4 -> 21203585
A5: GP per Active | B5: ='10_Income_Statement'!B6/'40_Customers_Orders'!B8 -> 18.8 | C5: ='10_Income_Statement'!C6/'40_Customers_Orders'!C8 -> 18.8 | D5: ='10_Income_Statement'!D6/'40_Customers_Orders'!D8 -> 18.8 | E5: ='10_Income_Statement'!E6/'40_Customers_Orders'!E8 -> 18.8 | F5: ='10_Income_Statement'!F6/'40_Customers_Orders'!F8 -> 18.8 | G5: ='10_Income_Statement'!G6/'40_Customers_Orders'!G8 -> 18.8 | H5: ='10_Income_Statement'!H6/'40_Customers_Orders'!H8 -> 18.8 | I5: ='10_Income_Statement'!I6/'40_Customers_Orders'!I8 -> 18.8 | ... AK5: ='10_Income_Statement'!AK6/'40_Customers_Orders'!AK8 -> 19.766749 | AL5: =AVERAGEIF('23_Time'!$B$3:$AK$3, 1,B5:AK5) -> 18.943877 | AM5: =AVERAGEIF('23_Time'!$B$3:$AK$3, 2,B5:AK5) -> 19.54234 | AN5: =AVERAGEIF('23_Time'!$B$3:$AK$3, 3,B5:AK5) -> 19.712467
A6: Lifetime Value | B6: =B5/'32_Inputs_GrowthRetention'!$D$9 -> 537.14286 | C6: =C5/'32_Inputs_GrowthRetention'!$D$9 -> 537.14286 | D6: =D5/'32_Inputs_GrowthRetention'!$D$9 -> 537.14286 | E6: =E5/'32_Inputs_GrowthRetention'!$D$9 -> 537.14286 | F6: =F5/'32_Inputs_GrowthRetention'!$D$9 -> 537.14286 | G6: =G5/'32_Inputs_GrowthRetention'!$D$9 -> 537.14286 | H6: =H5/'32_Inputs_GrowthRetention'!$D$9 -> 537.14286 | I6: =I5/'32_Inputs_GrowthRetention'!$D$9 -> 537.14286 | ... AK6: =AK5/'32_Inputs_GrowthRetention'!$D$9 -> 564.76427 | AL6: =M6 -> 552.31412 | AM6: =Y6 -> 561.47368 | AN6: =AK6 -> 564.76427
A7: CAC Payback Period | B7: ='42_OPEX'!B9/B5 -> 5.8510638 | C7: ='42_OPEX'!C9/C5 -> 5.8218085 | D7: ='42_OPEX'!D9/D5 -> 5.7926995 | E7: ='42_OPEX'!E9/E5 -> 5.763736 | F7: ='42_OPEX'!F9/F5 -> 5.7349173 | G7: ='42_OPEX'!G9/G5 -> 5.7062427 | H7: ='42_OPEX'!H9/H5 -> 5.6777115 | I7: ='42_OPEX'!I9/I5 -> 5.6493229 | ... AK7: ='42_OPEX'!AK9/AK5 -> 4.6694449 | AL7: =M7 -> 5.3850828 | AM7: =Y7 -> 4.987996 | AN7: =AK7 -> 4.6694449
A8: LTV / CAC Ratio | B8: =B6/'42_OPEX'!B9 -> 4.8831169 | C8: =C6/'42_OPEX'!C9 -> 4.9076552 | D8: =D6/'42_OPEX'!D9 -> 4.9323167 | E8: =E6/'42_OPEX'!E9 -> 4.9571023 | F8: =F6/'42_OPEX'!F9 -> 4.9820123 | G8: =G6/'42_OPEX'!G9 -> 5.0070476 | H8: =H6/'42_OPEX'!H9 -> 5.0322086 | I8: =I6/'42_OPEX'!I9 -> 5.0574961 | ... AK8: =AK6/'42_OPEX'!AK9 -> 6.1188062 | AL8: =M8 -> 5.3056619 | AM8: =Y8 -> 5.7280376 | AN8: =AK8 -> 6.1188062
A9: Gross Profit Margin | B9: ='10_Income_Statement'!B6/'10_Income_Statement'!B3 -> 0.80686695 | C9: ='10_Income_Statement'!C6/'10_Income_Statement'!C3 -> 0.80686695 | D9: ='10_Income_Statement'!D6/'10_Income_Statement'!D3 -> 0.80686695 | E9: ='10_Income_Statement'!E6/'10_Income_Statement'!E3 -> 0.80686695 | F9: ='10_Income_Statement'!F6/'10_Income_Statement'!F3 -> 0.80686695 | G9: ='10_Income_Statement'!G6/'10_Income_Statement'!G3 -> 0.80686695 | H9: ='10_Income_Statement'!H6/'10_Income_Statement'!H3 -> 0.80686695 | I9: ='10_Income_Statement'!I6/'10_Income_Statement'!I3 -> 0.80686695 | ... AN9: ='10_Income_Statement'!AN6/'10_Income_Statement'!AN3 -> 0.81419302
A10: EBITDA Margin | B10: ='10_Income_Statement'!B8/'10_Income_Statement'!B3 -> -32.958344 | C10: ='10_Income_Statement'!C8/'10_Income_Statement'!C3 -> -16.652868 | D10: ='10_Income_Statement'!D8/'10_Income_Statement'!D3 -> -11.203519 | E10: ='10_Income_Statement'!E8/'10_Income_Statement'!E3 -> -8.4678706 | F10: ='10_Income_Statement'!F8/'10_Income_Statement'!F3 -> -6.817472 | G10: ='10_Income_Statement'!G8/'10_Income_Statement'!G3 -> -5.7095352 | H10: ='10_Income_Statement'!H8/'10_Income_Statement'!H3 -> -4.9114616 | I10: ='10_Income_Statement'!I8/'10_Income_Statement'!I3 -> -4.3069739 | ... AN10: ='10_Income_Statement'!AN8/'10_Income_Statement'!AN3 -> -0.51265641
A11: Burn | B11: =IF('10_Income_Statement'!B8<0,-'10_Income_Statement'!B8,0) -> 1305480 | C11: =IF('10_Income_Statement'!C8<0,-'10_Income_Statement'!C8,0) -> 1335800 | D11: =IF('10_Income_Statement'!D8<0,-'10_Income_Statement'!D8,0) -> 1365945.6 | E11: =IF('10_Income_Statement'!E8<0,-'10_Income_Statement'!E8,0) -> 1395867.7 | F11: =IF('10_Income_Statement'!F8<0,-'10_Income_Statement'!F8,0) -> 1425515.3 | G11: =IF('10_Income_Statement'!G8<0,-'10_Income_Statement'!G8,0) -> 1454835.3 | H11: =IF('10_Income_Statement'!H8<0,-'10_Income_Statement'!H8,0) -> 1483772.3 | I11: =IF('10_Income_Statement'!I8<0,-'10_Income_Statement'!I8,0) -> 1512268.6 | ... AK11: =IF('10_Income_Statement'!AK8<0,-'10_Income_Statement'!AK8,0) -> 863035.13 | AL11: =M11 -> 1607663.2 | AM11: =Y11 -> 1499067.2 | AN11: =AK11 -> 863035.13
A12: Burn Multiple | B12: =B11/'10_Income_Statement'!B3 -> 32.958344 | C12: =C11/('10_Income_Statement'!C3-'10_Income_Statement'!B3) -> 32.897905 | D12: =D11/('10_Income_Statement'!D3-'10_Income_Statement'!C3) -> 32.751216 | E12: =E11/('10_Income_Statement'!E3-'10_Income_Statement'!D3) -> 32.521255 | F12: =F11/('10_Income_Statement'!F3-'10_Income_Statement'!E3) -> 32.211744 | G12: =G11/('10_Income_Statement'!G3-'10_Income_Statement'!F3) -> 31.827045 | H12: =H11/('10_Income_Statement'!H3-'10_Income_Statement'!G3) -> 31.372036 | I12: =I11/('10_Income_Statement'!I3-'10_Income_Statement'!H3) -> 30.851999 | J12: =J11/('10_Income_Statement'!J3-'10_Income_Statement'!I3) -> 27.21558 | ... AK12: =AK11/('10_Income_Statement'!AK3-'10_Income_Statement'!AJ3) -> 6.1351467 | AL12: =M12 -> 26.802941 | AM12: =Y12 -> 14.059529 | AN12: =AK12 -> 6.1351467
A13: Runway | B13: =IF('12_Balance Sheet'!B4<=0,0,IF(B11<=0,999,'12_Balance Sheet'!B4/'03_KPIs'!B11)) -> 2.781362 | C13: =IF('12_Balance Sheet'!C4<=0,0,IF(C11<=0,999,'12_Balance Sheet'!C4/'03_KPIs'!C11)) -> 1.6687583 | D13: =IF('12_Balance Sheet'!D4<=0,0,IF(D11<=0,999,'12_Balance Sheet'!D4/'03_KPIs'!D11)) -> 0.58165469 | E13: =IF('12_Balance Sheet'!E4<=0,0,IF(E11<=0,999,'12_Balance Sheet'!E4/'03_KPIs'!E11)) -> 0 | F13: =IF('12_Balance Sheet'!F4<=0,0,IF(F11<=0,999,'12_Balance Sheet'!F4/'03_KPIs'!F11)) -> 0 | G13: =IF('12_Balance Sheet'!G4<=0,0,IF(G11<=0,999,'12_Balance Sheet'!G4/'03_KPIs'!G11)) -> 15.323019 | H13: =IF('12_Balance Sheet'!H4<=0,0,IF(H11<=0,999,'12_Balance Sheet'!H4/'03_KPIs'!H11)) -> 13.965234 | I13: =IF('12_Balance Sheet'!I4<=0,0,IF(I11<=0,999,'12_Balance Sheet'!I4/'03_KPIs'!I11)) -> 12.642493 | ... AK13: =IF('12_Balance Sheet'!AK4<=0,0,IF(AK11<=0,999,'12_Balance Sheet'!AK4/'03_KPIs'!AK11)) -> 0 | AL13: =M13 -> 7.9270098 | AM13: =Y13 -> 0 | AN13: =AK13 -> 0
A14: Net Debt | B14: ='12_Balance Sheet'!B11-'12_Balance Sheet'!B4 -> -3631012.5 | C14: ='12_Balance Sheet'!C11-'12_Balance Sheet'!C4 -> -2229127.3 | D14: ='12_Balance Sheet'!D11-'12_Balance Sheet'!D4 -> -794508.68 | E14: ='12_Balance Sheet'!E11-'12_Balance Sheet'!E4 -> 672630.55 | F14: ='12_Balance Sheet'!F11-'12_Balance Sheet'!F4 -> 2172026.9 | G14: ='12_Balance Sheet'!G11-'12_Balance Sheet'!G4 -> -21292469 | H14: ='12_Balance Sheet'!H11-'12_Balance Sheet'!H4 -> -19721228 | I14: ='12_Balance Sheet'!I11-'12_Balance Sheet'!I4 -> -18118844 | ... AN14: ='12_Balance Sheet'!AN11-'12_Balance Sheet'!AN4 -> 34289184
A15: D / E Ratio | B15: ='12_Balance Sheet'!B11/(SUM('12_Balance Sheet'!B13:B14)) -> 0 | C15: ='12_Balance Sheet'!C11/(SUM('12_Balance Sheet'!C13:C14)) -> 0 | D15: ='12_Balance Sheet'!D11/(SUM('12_Balance Sheet'!D13:D14)) -> 0 | E15: ='12_Balance Sheet'!E11/(SUM('12_Balance Sheet'!E13:E14)) -> 0 | F15: ='12_Balance Sheet'!F11/(SUM('12_Balance Sheet'!F13:F14)) -> 0 | G15: ='12_Balance Sheet'!G11/(SUM('12_Balance Sheet'!G13:G14)) -> 0.0461105 | H15: ='12_Balance Sheet'!H11/(SUM('12_Balance Sheet'!H13:H14)) -> 0.049542634 | I15: ='12_Balance Sheet'!I11/(SUM('12_Balance Sheet'!I13:I14)) -> 0.053613692 | ... AN15: ='12_Balance Sheet'!AN11/(SUM('12_Balance Sheet'!AN13:AN14)) -> -0.087079258
A16: Loan Book | B16: ='12_Balance Sheet'!B6/'10_Income_Statement'!B3 -> 0 | C16: ='12_Balance Sheet'!C6/'10_Income_Statement'!C3 -> 0 | D16: ='12_Balance Sheet'!D6/'10_Income_Statement'!D3 -> 0 | E16: ='12_Balance Sheet'!E6/'10_Income_Statement'!E3 -> 0 | F16: ='12_Balance Sheet'!F6/'10_Income_Statement'!F3 -> 0 | G16: ='12_Balance Sheet'!G6/'10_Income_Statement'!G3 -> 0 | H16: ='12_Balance Sheet'!H6/'10_Income_Statement'!H3 -> 0 | I16: ='12_Balance Sheet'!I6/'10_Income_Statement'!I3 -> 0 | ... AN16: ='12_Balance Sheet'!AN6/'10_Income_Statement'!AN3 -> 0.29853603

Sheet 10_Income_Statement
A1: {='23_Time'!A1:AK2} -> Month Index | B1: 1 | C1: 2 | D1: 3 | E1: 4 | F1: 5 | G1: 6 | H1: 7 | I1: 8 | J1: 9 | K1: 10 | L1: 11 | M1: 12 | N1: 13 | O1: 14 | P1: 15 | Q1: 16 | R1: 17 | S1: 18 | T1: 19 | U1: 20 | V1: 21 | W1: 22 | X1: 23 | Y1: 24 | Z1: 25 | AA1: 26 | AB1: 27 | AC1: 28 | AD1: 29 | AE1: 30 | AF1: 31 | AG1: 32 | AH1: 33 | AI1: 34 | AJ1: 35 | AK1: 36
A2: Month Label | B2: M1 | C2: M2 | D2: M3 | E2: M4 | F2: M5 | G2: M6 | H2: M7 | I2: M8 | J2: M9 | K2: M10 | L2: M11 | M2: M12 | N2: M13 | O2: M14 | P2: M15 | Q2: M16 | R2: M17 | S2: M18 | T2: M19 | U2: M20 | V2: M21 | W2: M22 | X2: M23 | Y2: M24 | Z2: M25 | AA2: M26 | AB2: M27 | AC2: M28 | AD2: M29 | AE2: M30 | AF2: M31 | AG2: M32 | AH2: M33 | AI2: M34 | AJ2: M35 | AK2: M36 | AL2: Y1 Total | AM2: Y2 Total | AN2: Y3 Total
A3: Total Revenue | B3: ='41_Revenue_COGS'!B18 -> 39610 | C3: ='41_Revenue_COGS'!C18 -> 80214.409 | D3: ='41_Revenue_COGS'!D18 -> 121921.12 | E3: ='41_Revenue_COGS'!E18 -> 164842.83 | F3: ='41_Revenue_COGS'!F18 -> 209097.35 | G3: ='41_Revenue_COGS'!G18 -> 254808.01 | H3: ='41_Revenue_COGS'!H18 -> 302104.03 | I3: ='41_Revenue_COGS'!I18 -> 351120.91 | ... AK3: ='41_Revenue_COGS'!AK18 -> 3249171.9 | AL3: =SUMIF('23_Time'!$B$3:$AK$3, 1,B3:AK3) -> 3494582.3 | AM3: =SUMIF('23_Time'!$B$3:$AK$3, 2,B3:AK3) -> 12810192 | AN3: =SUMIF('23_Time'!$B$3:$AK$3, 3,B3:AK3) -> 29279351
A4: Processing Cost | B4: ='41_Revenue_COGS'!B5 -> 5355 | C4: ='41_Revenue_COGS'!C5 -> 10844.437 | D4: ='41_Revenue_COGS'!D5 -> 16482.899 | E4: ='41_Revenue_COGS'!E5 -> 22285.619 | F4: ='41_Revenue_COGS'!F5 -> 28268.526 | G4: ='41_Revenue_COGS'!G5 -> 34448.294 | H4: ='41_Revenue_COGS'!H5 -> 40842.39 | I4: ='41_Revenue_COGS'!I5 -> 47469.135 | ... AK4: ='41_Revenue_COGS'!AK5 -> 421766.06 | AL4: =SUMIF('23_Time'!$B$3:$AK$3, 1,B4:AK4) -> 467487.05 | AM4: =SUMIF('23_Time'!$B$3:$AK$3, 2,B4:AK4) -> 1676853.5 | AN4: =SUMIF('23_Time'!$B$3:$AK$3, 3,B4:AK4) -> 3808215.5
A5: Chargebacks | B5: ='41_Revenue_COGS'!B6 -> 2295 | C5: ='41_Revenue_COGS'!C6 -> 4647.616 | D5: ='41_Revenue_COGS'!D6 -> 7064.0994 | E5: ='41_Revenue_COGS'!E6 -> 9550.9794 | F5: ='41_Revenue_COGS'!F6 -> 12115.083 | G5: ='41_Revenue_COGS'!G6 -> 14763.554 | H5: ='41_Revenue_COGS'!H6 -> 17503.882 | I5: ='41_Revenue_COGS'!I6 -> 20343.915 | ... AK5: ='41_Revenue_COGS'!AK6 -> 180756.88 | AL5: =SUMIF('23_Time'!$B$3:$AK$3, 1,B5:AK5) -> 200351.59 | AM5: =SUMIF('23_Time'!$B$3:$AK$3, 2,B5:AK5) -> 718651.51 | AN5: =SUMIF('23_Time'!$B$3:$AK$3, 3,B5:AK5) -> 1632092.4
A6: Gross Profit | B6: =B3-B4-B5 -> 31960 | C6: =C3-C4-C5 -> 64722.356 | D6: =D3-D4-D5 -> 98374.125 | E6: =E3-E4-E5 -> 133006.23 | F6: =F3-F4-F5 -> 168713.74 | G6: =G3-G4-G5 -> 205596.17 | H6: =H3-H4-H5 -> 243757.76 | I6: =I3-I4-I5 -> 283307.85 | ... AK6: =AK3-AK4-AK5 -> 2646648.9 | AL6: =SUMIF('23_Time'!$B$3:$AK$3, 1,B6:AK6) -> 2826743.6 | AM6: =SUMIF('23_Time'!$B$3:$AK$3, 2,B6:AK6) -> 10414687 | AN6: =SUMIF('23_Time'!$B$3:$AK$3, 3,B6:AK6) -> 23839044
A7: Total Opex | B7: ='42_OPEX'!B13 -> 1337440 | C7: ='42_OPEX'!C13 -> 1400522.4 | D7: ='42_OPEX'!D13 -> 1464319.7 | E7: ='42_OPEX'!E13 -> 1528874 | F7: ='42_OPEX'!F13 -> 1594229.1 | G7: ='42_OPEX'!G13 -> 1660431.5 | H7: ='42_OPEX'!H13 -> 1727530.1 | I7: ='42_OPEX'!I13 -> 1795576.4 | ... AK7: ='42_OPEX'!AK13 -> 3509684 | AL7: =SUMIF('23_Time'!$B$3:$AK$3, 1,B7:AK7) -> 20392611 | AM7: =SUMIF('23_Time'!$B$3:$AK$3, 2,B7:AK7) -> 29213551 | AN7: =SUMIF('23_Time'!$B$3:$AK$3, 3,B7:AK7) -> 38849291
A8: EBITDA | B8: =B6-B7 -> -1305480 | C8: =C6-C7 -> -1335800 | D8: =D6-D7 -> -1365945.6 | E8: =E6-E7 -> -1395867.7 | F8: =F6-F7 -> -1425515.3 | G8: =G6-G7 -> -1454835.3 | H8: =H6-H7 -> -1483772.3 | I8: =I6-I7 -> -1512268.6 | ... AK8: =AK6-AK7 -> -863035.13 | AL8: =SUMIF('23_Time'!$B$3:$AK$3, 1,B8:AK8) -> -17565867 | AM8: =SUMIF('23_Time'!$B$3:$AK$3, 2,B8:AK8) -> -18798865 | AN8: =SUMIF('23_Time'!$B$3:$AK$3, 3,B8:AK8) -> -15010247
A9: Depreciation | B9: ='43_CAPEX_Depreciation'!B7 -> 0 | C9: ='43_CAPEX_Depreciation'!C7 -> 1660.4444 | D9: ='43_CAPEX_Depreciation'!D7 -> 3343.7654 | E9: ='43_CAPEX_Depreciation'!E7 -> 5049.3275 | F9: ='43_CAPEX_Depreciation'!F7 -> 6776.5129 | G9: ='43_CAPEX_Depreciation'!G7 -> 8524.7208 | H9: ='43_CAPEX_Depreciation'!H7 -> 10293.367 | I9: ='43_CAPEX_Depreciation'!I7 -> 12081.885 | ... AK9: ='43_CAPEX_Depreciation'!AK7 -> 60516.524 | AL9: =SUMIF('23_Time'!$B$3:$AK$3, 1,B9:AK9) -> 114321.16 | AM9: =SUMIF('23_Time'!$B$3:$AK$3, 2,B9:AK9) -> 374985.14 | AN9: =SUMIF('23_Time'!$B$3:$AK$3, 3,B9:AK9) -> 619963.37
A10: EBIT | B10: =B8-B9 -> -1305480 | C10: =C8-C9 -> -1337460.4 | D10: =D8-D9 -> -1369289.4 | E10: =E8-E9 -> -1400917.1 | F10: =F8-F9 -> -1432291.9 | G10: =G8-G9 -> -1463360.1 | H10: =H8-H9 -> -1494065.7 | I10: =I8-I9 -> -1524350.4 | ... AK10: =AK8-AK9 -> -923551.65 | AL10: =SUMIF('23_Time'!$B$3:$AK$3, 1,B10:AK10) -> -17680188 | AM10: =SUMIF('23_Time'!$B$3:$AK$3, 2,B10:AK10) -> -19173850 | AN10: =SUMIF('23_Time'!$B$3:$AK$3, 3,B10:AK10) -> -15630211
A11: Interest Expense | B11: ='45_Funding_Interest_Equity'!B6 -> 0 | C11: ='45_Funding_Interest_Equity'!C6 -> 0 | D11: ='45_Funding_Interest_Equity'!D6 -> 0 | E11: ='45_Funding_Interest_Equity'!E6 -> 0 | F11: ='45_Funding_Interest_Equity'!F6 -> 0 | G11: ='45_Funding_Interest_Equity'!G6 -> 4166.6667 | H11: ='45_Funding_Interest_Equity'!H6 -> 8333.3333 | I11: ='45_Funding_Interest_Equity'!I6 -> 8333.3333 | ... AK11: ='45_Funding_Interest_Equity'!AK6 -> 16666.667 | AL11: =SUMIF('23_Time'!$B$3:$AK$3, 1,B11:AK11) -> 83333.333 | AM11: =SUMIF('23_Time'!$B$3:$AK$3, 2,B11:AK11) -> 200000 | AN11: =SUMIF('23_Time'!$B$3:$AK$3, 3,B11:AK11) -> 200000
A12: EBT | B12: =B10-B11 -> -1305480 | C12: =C10-C11 -> -1337460.4 | D12: =D10-D11 -> -1369289.4 | E12: =E10-E11 -> -1400917.1 | F12: =F10-F11 -> -1432291.9 | G12: =G10-G11 -> -1467526.7 | H12: =H10-H11 -> -1502399 | I12: =I10-I11 -> -1532683.8 | ... AK12: =AK10-AK11 -> -940218.32 | AL12: =SUMIF('23_Time'!$B$3:$AK$3, 1,B12:AK12) -> -17763521 | AM12: =SUMIF('23_Time'!$B$3:$AK$3, 2,B12:AK12) -> -19373850 | AN12: =SUMIF('23_Time'!$B$3:$AK$3, 3,B12:AK12) -> -15830211
A13: Cumulative EBT | B13: =B12 -> -1305480 | C13: =C12+B13 -> -2642940.4 | D13: =D12+C13 -> -4012229.8 | E13: =E12+D13 -> -5413146.9 | F13: =F12+E13 -> -6845438.8 | G13: =G12+F13 -> -8312965.5 | H13: =H12+G13 -> -9815364.5 | I13: =I12+H13 -> -11348048 | J13: =J12+I13 -> -12909189 | ... AK13: =AK12+AJ13 -> -52967582 | AL13: =M13 -> -17763521 | AM13: =Y13 -> -37137371 | AN13: =AK13 -> -52967582
A14: Tax | B14: =IF(B13<=0,0,B12*'37_Inputs_Tax'!$B$2) -> 0 | C14: =IF(C13<=0,0,C12*'37_Inputs_Tax'!$B$2) -> 0 | D14: =IF(D13<=0,0,D12*'37_Inputs_Tax'!$B$2) -> 0 | E14: =IF(E13<=0,0,E12*'37_Inputs_Tax'!$B$2) -> 0 | F14: =IF(F13<=0,0,F12*'37_Inputs_Tax'!$B$2) -> 0 | G14: =IF(G13<=0,0,G12*'37_Inputs_Tax'!$B$2) -> 0 | H14: =IF(H13<=0,0,H12*'37_Inputs_Tax'!$B$2) -> 0 | I14: =IF(I13<=0,0,I12*'37_Inputs_Tax'!$B$2) -> 0 | ... AK14: =IF(AK13<=0,0,AK12*'37_Inputs_Tax'!$B$2) -> 0 | AL14: =SUMIF('23_Time'!$B$3:$AK$3, 1,B14:AK14) -> 0 | AM14: =SUMIF('23_Time'!$B$3:$AK$3, 2,B14:AK14) -> 0 | AN14: =SUMIF('23_Time'!$B$3:$AK$3, 3,B14:AK14) -> 0
A15: Net Income | B15: =B12-B14 -> -1305480 | C15: =C12-C14 -> -1337460.4 | D15: =D12-D14 -> -1369289.4 | E15: =E12-E14 -> -1400917.1 | F15: =F12-F14 -> -1432291.9 | G15: =G12-G14 -> -1467526.7 | H15: =H12-H14 -> -1502399 | I15: =I12-I14 -> -1532683.8 | ... AK15: =AK12-AK14 -> -940218.32 | AL15: =SUMIF('23_Time'!$B$3:$AK$3, 1,B15:AK15) -> -17763521 | AM15: =SUMIF('23_Time'!$B$3:$AK$3, 2,B15:AK15) -> -19373850 | AN15: =SUMIF('23_Time'!$B$3:$AK$3, 3,B15:AK15) -> -15830211

Sheet 11_Cash_Flow
A1: {='23_Time'!A1:AK2} -> Month Index | B1: 1 | C1: 2 | D1: 3 | E1: 4 | F1: 5 | G1: 6 | H1: 7 | I1: 8 | J1: 9 | K1: 10 | L1: 11 | M1: 12 | N1: 13 | O1: 14 | P1: 15 | Q1: 16 | R1: 17 | S1: 18 | T1: 19 | U1: 20 | V1: 21 | W1: 22 | X1: 23 | Y1: 24 | Z1: 25 | AA1: 26 | AB1: 27 | AC1: 28 | AD1: 29 | AE1: 30 | AF1: 31 | AG1: 32 | AH1: 33 | AI1: 34 | AJ1: 35 | AK1: 36
A2: Month Label | B2: M1 | C2: M2 | D2: M3 | E2: M4 | F2: M5 | G2: M6 | H2: M7 | I2: M8 | J2: M9 | K2: M10 | L2: M11 | M2: M12 | N2: M13 | O2: M14 | P2: M15 | Q2: M16 | R2: M17 | S2: M18 | T2: M19 | U2: M20 | V2: M21 | W2: M22 | X2: M23 | Y2: M24 | Z2: M25 | AA2: M26 | AB2: M27 | AC2: M28 | AD2: M29 | AE2: M30 | AF2: M31 | AG2: M32 | AH2: M33 | AI2: M34 | AJ2: M35 | AK2: M36 | AL2: Y1 Total | AM2: Y2 Total | AN2: Y3 Total
A3: Net Income | B3: ='10_Income_Statement'!B15 -> -1305480 | C3: ='10_Income_Statement'!C15 -> -1337460.4 | D3: ='10_Income_Statement'!D15 -> -1369289.4 | E3: ='10_Income_Statement'!E15 -> -1400917.1 | F3: ='10_Income_Statement'!F15 -> -1432291.9 | G3: ='10_Income_Statement'!G15 -> -1467526.7 | H3: ='10_Income_Statement'!H15 -> -1502399 | I3: ='10_Income_Statement'!I15 -> -1532683.8 | ... AK3: ='10_Income_Statement'!AK15 -> -940218.32 | AL3: =SUMIF('23_Time'!$B$3:$AK$3, 1,B3:AK3) -> -17763521 | AM3: =SUMIF('23_Time'!$B$3:$AK$3, 2,B3:AK3) -> -19373850 | AN3: =SUMIF('23_Time'!$B$3:$AK$3, 3,B3:AK3) -> -15830211
A4: Depreciation | B4: ='10_Income_Statement'!B9 -> 0 | C4: ='10_Income_Statement'!C9 -> 1660.4444 | D4: ='10_Income_Statement'!D9 -> 3343.7654 | E4: ='10_Income_Statement'!E9 -> 5049.3275 | F4: ='10_Income_Statement'!F9 -> 6776.5129 | G4: ='10_Income_Statement'!G9 -> 8524.7208 | H4: ='10_Income_Statement'!H9 -> 10293.367 | I4: ='10_Income_Statement'!I9 -> 12081.885 | ... AK4: ='10_Income_Statement'!AK9 -> 60516.524 | AL4: =SUMIF('23_Time'!$B$3:$AK$3, 1,B4:AK4) -> 114321.16 | AM4: =SUMIF('23_Time'!$B$3:$AK$3, 2,B4:AK4) -> 374985.14 | AN4: =SUMIF('23_Time'!$B$3:$AK$3, 3,B4:AK4) -> 619963.37
A5: Change in AR | B5: =-'44_Working_Capital'!B7 -> -15844 | C5: ='44_Working_Capital'!B7-'44_Working_Capital'!C7 -> -16241.764 | D5: ='44_Working_Capital'!C7-'44_Working_Capital'!D7 -> -16682.686 | E5: ='44_Working_Capital'!D7-'44_Working_Capital'!E7 -> -17168.682 | F5: ='44_Working_Capital'!E7-'44_Working_Capital'!F7 -> -17701.809 | G5: ='44_Working_Capital'!F7-'44_Working_Capital'!G7 -> -18284.265 | H5: ='44_Working_Capital'!G7-'44_Working_Capital'!H7 -> -18918.407 | I5: ='44_Working_Capital'!H7-'44_Working_Capital'!I7 -> -19606.75 | J5: ='44_Working_Capital'!I7-'44_Working_Capital'!J7 -> -22556.949 | ... AK5: ='44_Working_Capital'!AJ7-'44_Working_Capital'!AK7 -> -56268.263 | AL5: =SUMIF('23_Time'!$B$3:$AK$3, 1,B5:AK5) -> -232112.65 | AM5: =SUMIF('23_Time'!$B$3:$AK$3, 2,B5:AK5) -> -394828.69 | AN5: =SUMIF('23_Time'!$B$3:$AK$3, 3,B5:AK5) -> -672727.4
A6: Change in AP | B6: ='44_Working_Capital'!B8 -> 4462.5 | C6: ='44_Working_Capital'!C8-'44_Working_Capital'!B8 -> 4574.5311 | D6: ='44_Working_Capital'!D8-'44_Working_Capital'!C8 -> 4698.7178 | E6: ='44_Working_Capital'!E8-'44_Working_Capital'!D8 -> 4835.5999 | F6: ='44_Working_Capital'!F8-'44_Working_Capital'!E8 -> 4985.7562 | G6: ='44_Working_Capital'!G8-'44_Working_Capital'!F8 -> 5149.8065 | H6: ='44_Working_Capital'!H8-'44_Working_Capital'!G8 -> 5328.4139 | I6: ='44_Working_Capital'!I8-'44_Working_Capital'!H8 -> 5522.2874 | J6: ='44_Working_Capital'!J8-'44_Working_Capital'!I8 -> 5732.1841 | ... AK6: ='44_Working_Capital'!AK8-'44_Working_Capital'!AJ8 -> 15035.042 | AL6: =SUMIF('23_Time'!$B$3:$AK$3, 1,B6:AK6) -> 63918.412 | AM6: =SUMIF('23_Time'!$B$3:$AK$3, 2,B6:AK6) -> 106434.95 | AN6: =SUMIF('23_Time'!$B$3:$AK$3, 3,B6:AK6) -> 181118.36
A7: Change in Deferred Revenue | B7: ='44_Working_Capital'!B9 -> 7650 | C7: ='44_Working_Capital'!C9 - '44_Working_Capital'!B9 -> 7842.0533 | D7: ='44_Working_Capital'!D9 - '44_Working_Capital'!C9 -> 8054.9448 | E7: ='44_Working_Capital'!E9 - '44_Working_Capital'!D9 -> 8289.5999 | F7: ='44_Working_Capital'!F9 - '44_Working_Capital'!E9 -> 8547.0107 | G7: ='44_Working_Capital'!G9 - '44_Working_Capital'!F9 -> 8828.2396 | H7: ='44_Working_Capital'!H9 - '44_Working_Capital'!G9 -> 9134.4238 | I7: ='44_Working_Capital'!I9 - '44_Working_Capital'!H9 -> 9466.7783 | J7: ='44_Working_Capital'!J9 - '44_Working_Capital'!I9 -> 9826.6014 | ... AK7: ='44_Working_Capital'!AK9 - '44_Working_Capital'!AJ9 -> 25774.358 | AL7: =SUMIF('23_Time'!$B$3:$AK$3, 1,B7:AK7) -> 109574.42 | AM7: =SUMIF('23_Time'!$B$3:$AK$3, 2,B7:AK7) -> 182459.91 | AN7: =SUMIF('23_Time'!$B$3:$AK$3, 3,B7:AK7) -> 310488.62
A8: Change in Loan Balance | B8: ='44_Working_Capital'!B3-'44_Working_Capital'!B6 -> 0 | C8: ='44_Working_Capital'!C3-'44_Working_Capital'!C6 -> 0 | D8: ='44_Working_Capital'!D3-'44_Working_Capital'!D6 -> 0 | E8: ='44_Working_Capital'!E3-'44_Working_Capital'!E6 -> 0 | F8: ='44_Working_Capital'!F3-'44_Working_Capital'!F6 -> 0 | G8: ='44_Working_Capital'!G3-'44_Working_Capital'!G6 -> 0 | H8: ='44_Working_Capital'!H3-'44_Working_Capital'!H6 -> 0 | I8: ='44_Working_Capital'!I3-'44_Working_Capital'!I6 -> 0 | ... AK8: ='44_Working_Capital'!AK3-'44_Working_Capital'!AK6 -> -519964.48 | AL8: =SUMIF('23_Time'!$B$3:$AK$3, 1,B8:AK8) -> -666962.1 | AM8: =SUMIF('23_Time'!$B$3:$AK$3, 2,B8:AK8) -> -2919720.7 | AN8: =SUMIF('23_Time'!$B$3:$AK$3, 3,B8:AK8) -> -5154258.7
A9: Capex | B9: =-'43_CAPEX_Depreciation'!B5 -> -59776 | C9: =-'43_CAPEX_Depreciation'!C5 -> -62260 | D9: =-'43_CAPEX_Depreciation'!D5 -> -64744 | E9: =-'43_CAPEX_Depreciation'!E5 -> -67228 | F9: =-'43_CAPEX_Depreciation'!F5 -> -69712 | G9: =-'43_CAPEX_Depreciation'!G5 -> -72196 | H9: =-'43_CAPEX_Depreciation'!H5 -> -74680 | I9: =-'43_CAPEX_Depreciation'!I5 -> -77164 | ... AK9: =-'43_CAPEX_Depreciation'!AK5 -> -116908 | AL9: =SUMIF('23_Time'!$B$3:$AK$3, 1,B9:AK9) -> -881256 | AM9: =SUMIF('23_Time'!$B$3:$AK$3, 2,B9:AK9) -> -1142076 | AN9: =SUMIF('23_Time'!$B$3:$AK$3, 3,B9:AK9) -> -1320924
A10: Debt Draw | B10: ='45_Funding_Interest_Equity'!B4 -> 0 | C10: ='45_Funding_Interest_Equity'!C4 -> 0 | D10: ='45_Funding_Interest_Equity'!D4 -> 0 | E10: ='45_Funding_Interest_Equity'!E4 -> 0 | F10: ='45_Funding_Interest_Equity'!F4 -> 0 | G10: ='45_Funding_Interest_Equity'!G4 -> 1000000 | H10: ='45_Funding_Interest_Equity'!H4 -> 0 | I10: ='45_Funding_Interest_Equity'!I4 -> 0 | ... AK10: ='45_Funding_Interest_Equity'!AK4 -> 0 | AL10: =SUMIF('23_Time'!$B$3:$AK$3, 1,B10:AK10) -> 2000000 | AM10: =SUMIF('23_Time'!$B$3:$AK$3, 2,B10:AK10) -> 0 | AN10: =SUMIF('23_Time'!$B$3:$AK$3, 3,B10:AK10) -> 0
A11: Equity Raise | B11: ='45_Funding_Interest_Equity'!B7 -> 0 | C11: ='45_Funding_Interest_Equity'!C7 -> 0 | D11: ='45_Funding_Interest_Equity'!D7 -> 0 | E11: ='45_Funding_Interest_Equity'!E7 -> 0 | F11: ='45_Funding_Interest_Equity'!F7 -> 0 | G11: ='45_Funding_Interest_Equity'!G7 -> 25000000 | H11: ='45_Funding_Interest_Equity'!H7 -> 0 | I11: ='45_Funding_Interest_Equity'!I7 -> 0 | ... AK11: ='45_Funding_Interest_Equity'!AK7 -> 0 | AL11: =SUMIF('23_Time'!$B$3:$AK$3, 1,B11:AK11) -> 25000000 | AM11: =SUMIF('23_Time'!$B$3:$AK$3, 2,B11:AK11) -> 0 | AN11: =SUMIF('23_Time'!$B$3:$AK$3, 3,B11:AK11) -> 0
A12: Net Change in Cash | B12: =SUM(B3:B11) -> -1368987.5 | C12: =SUM(C3:C11) -> -1401885.2 | D12: =SUM(D3:D11) -> -1434618.6 | E12: =SUM(E3:E11) -> -1467139.2 | F12: =SUM(F3:F11) -> -1499396.4 | G12: =SUM(G3:G11) -> 24464496 | H12: =SUM(H3:H11) -> -1571241.2 | I12: =SUM(I3:I11) -> -1602383.6 | ... AK12: =SUM(AK3:AK11) -> -1532033.1 | AL12: =SUMIF('23_Time'!$B$3:$AK$3, 1,B12:AK12) -> 7743961.8 | AM12: =SUMIF('23_Time'!$B$3:$AK$3, 2,B12:AK12) -> -23166595 | AN12: =SUMIF('23_Time'!$B$3:$AK$3, 3,B12:AK12) -> -21866550

Sheet 12_Balance Sheet
A1: {='23_Time'!A1:AK2} -> Month Index | B1: 1 | C1: 2 | D1: 3 | E1: 4 | F1: 5 | G1: 6 | H1: 7 | I1: 8 | J1: 9 | K1: 10 | L1: 11 | M1: 12 | N1: 13 | O1: 14 | P1: 15 | Q1: 16 | R1: 17 | S1: 18 | T1: 19 | U1: 20 | V1: 21 | W1: 22 | X1: 23 | Y1: 24 | Z1: 25 | AA1: 26 | AB1: 27 | AC1: 28 | AD1: 29 | AE1: 30 | AF1: 31 | AG1: 32 | AH1: 33 | AI1: 34 | AJ1: 35 | AK1: 36
A2: Month Label | B2: M1 | C2: M2 | D2: M3 | E2: M4 | F2: M5 | G2: M6 | H2: M7 | I2: M8 | J2: M9 | K2: M10 | L2: M11 | M2: M12 | N2: M13 | O2: M14 | P2: M15 | Q2: M16 | R2: M17 | S2: M18 | T2: M19 | U2: M20 | V2: M21 | W2: M22 | X2: M23 | Y2: M24 | Z2: M25 | AA2: M26 | AB2: M27 | AC2: M28 | AD2: M29 | AE2: M30 | AF2: M31 | AG2: M32 | AH2: M33 | AI2: M34 | AJ2: M35 | AK2: M36 | AL2: Y1 Total | AM2: Y2 Total | AN2: Y3 Total
A3: Assets: | AL3: =SUMIF('23_Time'!$B$3:$AK$3, 1,$B$3:$AK$3) -> 0 | AM3: =SUMIF('23_Time'!$B$3:$AK$3, 2,$B$3:$AK$3) -> 0 | AN3: =SUMIF('23_Time'!$B$3:$AK$3, 3,$B$3:$AK$3) -> 0
A4: Cash | B4: ='36_Inputs_Funding'!B2+'11_Cash_Flow'!B12 -> 3631012.5 | C4: =B4+'11_Cash_Flow'!C12 -> 2229127.3 | D4: =C4+'11_Cash_Flow'!D12 -> 794508.68 | E4: =D4+'11_Cash_Flow'!E12 -> -672630.55 | F4: =E4+'11_Cash_Flow'!F12 -> -2172026.9 | G4: =F4+'11_Cash_Flow'!G12 -> 22292469 | H4: =G4+'11_Cash_Flow'!H12 -> 20721228 | I4: =H4+'11_Cash_Flow'!I12 -> 19118844 | J4: =I4+'11_Cash_Flow'!J12 -> 18329667 | ... AK4: =AJ4+'11_Cash_Flow'!AK12 -> -32289184 | AL4: =M4 -> 12743962 | AM4: =Y4 -> -10422634 | AN4: =AK4 -> -32289184
A5: Accounts Receivable | B5: ='44_Working_Capital'!B7 -> 15844 | C5: ='44_Working_Capital'!C7 -> 32085.764 | D5: ='44_Working_Capital'!D7 -> 48768.449 | E5: ='44_Working_Capital'!E7 -> 65937.132 | F5: ='44_Working_Capital'!F7 -> 83638.941 | G5: ='44_Working_Capital'!G7 -> 101923.21 | H5: ='44_Working_Capital'!H7 -> 120841.61 | I5: ='44_Working_Capital'!I7 -> 140448.36 | ... AK5: ='44_Working_Capital'!AK7 -> 1299668.7 | AL5: =M5 -> 232112.65 | AM5: =Y5 -> 626941.34 | AN5: =AK5 -> 1299668.7
A6: Loan Balance | B6: ='44_Working_Capital'!B6 -> 0 | C6: ='44_Working_Capital'!C6 -> 0 | D6: ='44_Working_Capital'!D6 -> 0 | E6: ='44_Working_Capital'!E6 -> 0 | F6: ='44_Working_Capital'!F6 -> 0 | G6: ='44_Working_Capital'!G6 -> 0 | H6: ='44_Working_Capital'!H6 -> 0 | I6: ='44_Working_Capital'!I6 -> 0 | ... AK6: ='44_Working_Capital'!AK6 -> 8740941.5 | AL6: =M6 -> 666962.1 | AM6: =Y6 -> 3586682.8 | AN6: =AK6 -> 8740941.5
A7: Net PP&E | B7: ='43_CAPEX_Depreciation'!B8 -> 59776 | C7: ='43_CAPEX_Depreciation'!C8 -> 120375.56 | D7: ='43_CAPEX_Depreciation'!D8 -> 181775.79 | E7: ='43_CAPEX_Depreciation'!E8 -> 243954.46 | F7: ='43_CAPEX_Depreciation'!F8 -> 306889.95 | G7: ='43_CAPEX_Depreciation'!G8 -> 370561.23 | H7: ='43_CAPEX_Depreciation'!H8 -> 434947.86 | I7: ='43_CAPEX_Depreciation'!I8 -> 500029.98 | ... AK7: ='43_CAPEX_Depreciation'!AK8 -> 2234986.3 | AL7: =M7 -> 766934.84 | AM7: =Y7 -> 1534025.7 | AN7: =AK7 -> 2234986.3
A8: Liabilities:
A9: Accounts Payables | B9: ='44_Working_Capital'!B8 -> 4462.5 | C9: ='44_Working_Capital'!C8 -> 9037.0311 | D9: ='44_Working_Capital'!D8 -> 13735.749 | E9: ='44_Working_Capital'!E8 -> 18571.349 | F9: ='44_Working_Capital'!F8 -> 23557.105 | G9: ='44_Working_Capital'!G8 -> 28706.911 | H9: ='44_Working_Capital'!H8 -> 34035.325 | I9: ='44_Working_Capital'!I8 -> 39557.613 | ... AK9: ='44_Working_Capital'!AK8 -> 351471.72 | AL9: =M9 -> 63918.412 | AM9: =Y9 -> 170353.36 | AN9: =AK9 -> 351471.72
A10: Deferred Revenue | B10: ='44_Working_Capital'!B9 -> 7650 | C10: ='44_Working_Capital'!C9 -> 15492.053 | D10: ='44_Working_Capital'!D9 -> 23546.998 | E10: ='44_Working_Capital'!E9 -> 31836.598 | F10: ='44_Working_Capital'!F9 -> 40383.609 | G10: ='44_Working_Capital'!G9 -> 49211.848 | H10: ='44_Working_Capital'!H9 -> 58346.272 | I10: ='44_Working_Capital'!I9 -> 67813.05 | ... AK10: ='44_Working_Capital'!AK9 -> 602522.95 | AL10: =M10 -> 109574.42 | AM10: =Y10 -> 292034.33 | AN10: =AK10 -> 602522.95
A11: Debt | B11: ='45_Funding_Interest_Equity'!B5 -> 0 | C11: ='45_Funding_Interest_Equity'!C5 -> 0 | D11: ='45_Funding_Interest_Equity'!D5 -> 0 | E11: ='45_Funding_Interest_Equity'!E5 -> 0 | F11: ='45_Funding_Interest_Equity'!F5 -> 0 | G11: ='45_Funding_Interest_Equity'!G5 -> 1000000 | H11: ='45_Funding_Interest_Equity'!H5 -> 1000000 | I11: ='45_Funding_Interest_Equity'!I5 -> 1000000 | ... AK11: ='45_Funding_Interest_Equity'!AK5 -> 2000000 | AL11: =M11 -> 2000000 | AM11: =Y11 -> 2000000 | AN11: =AK11 -> 2000000
A12: Equity:
A13: Share Capital | B13: ='36_Inputs_Funding'!$B$2 -> 5000000 | C13: =B13+'45_Funding_Interest_Equity'!C7 -> 5000000 | D13: =C13+'45_Funding_Interest_Equity'!D7 -> 5000000 | E13: =D13+'45_Funding_Interest_Equity'!E7 -> 5000000 | F13: =E13+'45_Funding_Interest_Equity'!F7 -> 5000000 | G13: =F13+'45_Funding_Interest_Equity'!G7 -> 30000000 | H13: =G13+'45_Funding_Interest_Equity'!H7 -> 30000000 | I13: =H13+'45_Funding_Interest_Equity'!I7 -> 30000000 | J13: =I13+'45_Funding_Interest_Equity'!J7 -> 30000000 | ... AK13: =AJ13+'45_Funding_Interest_Equity'!AK7 -> 30000000 | AL13: =M13 -> 30000000 | AM13: =Y13 -> 30000000 | AN13: =AK13 -> 30000000
A14: Retained Earnings | B14: ='10_Income_Statement'!B15 -> -1305480 | C14: =B14+'10_Income_Statement'!C15 -> -2642940.4 | D14: =C14+'10_Income_Statement'!D15 -> -4012229.8 | E14: =D14+'10_Income_Statement'!E15 -> -5413146.9 | F14: =E14+'10_Income_Statement'!F15 -> -6845438.8 | G14: =F14+'10_Income_Statement'!G15 -> -8312965.5 | H14: =G14+'10_Income_Statement'!H15 -> -9815364.5 | I14: =H14+'10_Income_Statement'!I15 -> -11348048 | J14: =I14+'10_Income_Statement'!J15 -> -12909189 | ... AK14: =AJ14+'10_Income_Statement'!AK15 -> -52967582 | AL14: =M14 -> -17763521 | AM14: =Y14 -> -37137371 | AN14: =AK14 -> -52967582
A17: Net Assets | B17: =SUM(B4:B7) -> 3706632.5 | C17: =SUM(C4:C7) -> 2381588.6 | D17: =SUM(D4:D7) -> 1025052.9 | E17: =SUM(E4:E7) -> -362738.95 | F17: =SUM(F4:F7) -> -1781498 | G17: =SUM(G4:G7) -> 22764953 | H17: =SUM(H4:H7) -> 21277017 | I17: =SUM(I4:I7) -> 19759322 | ... AK17: =SUM(AK4:AK7) -> -20013587 | AL17: =M17 -> 14409971 | AM17: =Y17 -> -4674983.7 | AN17: =AK17 -> -20013587
A18: Net Liabilities + equity | B18: =SUM(B9:B14) -> 3706632.5 | C18: =SUM(C9:C14) -> 2381588.6 | D18: =SUM(D9:D14) -> 1025052.9 | E18: =SUM(E9:E14) -> -362738.95 | F18: =SUM(F9:F14) -> -1781498 | G18: =SUM(G9:G14) -> 22764953 | H18: =SUM(H9:H14) -> 21277017 | I18: =SUM(I9:I14) -> 19759322 | ... AK18: =SUM(AK9:AK14) -> -20013587 | AL18: =M18 -> 14409971 | AM18: =Y18 -> -4674983.7 | AN18: =AK18 -> -20013587
A19: Balance Check | B19: =B17-B18 -> 0 | C19: =C17-C18 -> 0 | D19: =D17-D18 -> 0 | E19: =E17-E18 -> 0 | F19: =F17-F18 -> 0 | G19: =G17-G18 -> 0 | H19: =H17-H18 -> 0 | I19: =I17-I18 -> 0 | ... AN19: =AN17-AN18 -> 0

Sheet 20_Capital_Sensitivity
A1: Min Runway | H1: Equity Raise Month | I1: Equity Raise Amount
A2: =MIN('03_KPIs'!B13:AK13) -> 0 | B2: 10000000 | C2: 15000000 | D2: 20000000 | E2: 25000000 | H2: 6 | I2: 25000000
A3: 6 | B3: 0 | C3: 0 | D3: 0 | E3: 0
A4: 9 | B4: 0 | C4: 0 | D4: 0 | E4: 0
A5: 12 | B5: 0 | C5: 0 | D5: 0 | E5: 0
A7: First Negative Cash
A8: {=IFERROR(MATCH(TRUE, '12_Balance Sheet'!B4:AK4<0, 0), 99)} -> 4 | B8: 10000000 | C8: 15000000 | D8: 20000000 | E8: 25000000
A9: 6 | B9: 4 | C9: 4 | D9: 4 | E9: 4
A10: 9 | B10: 4 | C10: 4 | D10: 4 | E10: 4
A11: 12 | B11: 4 | C11: 4 | D11: 4 | E11: 4
A13: MinCash Pre-Raise
A14: =MIN(OFFSET('12_Balance Sheet'!B4, 0, 0, 1, $H$2-1)) -> -2172026.9 | B14: 10000000 | C14: 15000000 | D14: 20000000 | E14: 25000000
A15: 6 | B15: -2172026.9 | C15: -2172026.9 | D15: -2172026.9 | E15: -2172026.9
A16: 9 | B16: -5881156 | C16: -5881156 | D16: -5881156 | E16: -5881156
A17: 12 | B17: -10359729 | C17: -10359729 | D17: -10359729 | E17: -10359729
A19: Runway Post-Raise
A20: {=INDEX('03_KPIs'!B13:AK13, '20_Capital_Sensitivity'!$H$2+1)} -> 13.965234 | B20: 10000000 | C20: 15000000 | D20: 20000000 | E20: 25000000
A21: 6 | B21: 3.8558662 | C21: 7.2256554 | D21: 10.595445 | E21: 13.965234
A22: 9 | B22: 0.96315743 | C22: 4.1686566 | D22: 7.3741558 | E22: 10.579655
A23: 12 | B23: 0 | C23: 0.52292266 | D23: 3.6366209 | E23: 6.7503191

Sheet 21_Scenarios
A1: Variable | B1: Base | C1: Downside | D1: Upside | G1: Equity Raise Month | H1: Equity Raise Amount | I1: Minimum Runway Target
A2: Acquisition Growth Multiplier | B2: 1 | C2: 0.6 | D2: 1.25 | G2: ='20_Capital_Sensitivity'!H2 -> 6 | H2: ='20_Capital_Sensitivity'!I2 -> 25000000 | I2: ='20_Capital_Sensitivity'!J2 -> 0
A3: Churn Mult | B3: 1 | C3: 1.35 | D3: 0.8
A4: CAC Mult | B4: 1 | C4: 1.2 | D4: 0.9
A5: Take Rate Mult | B5: 1 | C5: 0.9 | D5: 1.05
A6: Raise Timing Shift (months) | B6: 0 | C6: 3 | D6: -2

Sheet 22_Scenario_Compare
A1: Metric | B1: Downside | C1: Base | D1: Upside
A2: Growth
A3: Revenue (Y3) | B3: 15546091 | C3: 29279351 | D3: 38866923
A4: ARR (M36) | B4: 11053772 | C4: 21203585 | D4: 26280797
A5: Active Customers (M36) | B5: 69472.253 | C5: 133893.99 | D5: 165596.2
A6: Profitability
A7: Gross Margin % (Y3) | B7: 0.80602103 | C7: 0.81825072 | D7: 0.81825072
A8: EBITDA Margin % (Y3) | B8: -1.3736224 | C8: -0.19561799 | D8: -0.19561799
A9: Net Income (Y3) | B9: -22174424 | C9: -15830211 | D9: -8423032.6
A10: Capital Efficiency
A11: Burn Multiple (M12) | B11: 39.221354 | C11: 26.802941 | D11: 20.3425
A12: LTV/CAC (M12) | B12: 3.0562921 | C12: 5.3056619 | D12: 7.6023532
A13: CAC Payback (M12) | B13: 6.9247376 | C13: 5.3850828 | D13: 4.6977935
A14: Liquidity
A15: Runway Post Raise | B15: 14 | C15: 14 | D15: 14
A16: Min Cash Pre Raise | B16: -2393128.7 | C16: -2172026.9 | D16: -2057032.3
A17: First Negative Cash Month | B17: 4 | C17: 4 | D17: 4
A18: Cash (M12) | B18: 12582484 | C18: 12743962 | D18: 12873809
A19: Capital Strategy (M6, 25m)
A20: Dilution % | B20: 0.76647181 | C20: 0.74411549 | D20: 0.73111086
A21: Net Debt (M36) | B21: 39214935 | C21: 34289184 | D21: 27457868

Sheet 23_Time
A1: Month Index | B1: 1 | C1: 2 | D1: 3 | E1: 4 | F1: 5 | G1: 6 | H1: 7 | I1: 8 | J1: 9 | K1: 10 | L1: 11 | M1: 12 | N1: 13 | O1: 14 | P1: 15 | Q1: 16 | R1: 17 | S1: 18 | T1: 19 | U1: 20 | V1: 21 | W1: 22 | X1: 23 | Y1: 24 | Z1: 25 | AA1: 26 | AB1: 27 | AC1: 28 | AD1: 29 | AE1: 30 | AF1: 31 | AG1: 32 | AH1: 33 | AI1: 34 | AJ1: 35 | AK1: 36
A2: Month Label | B2: M1 | C2: M2 | D2: M3 | E2: M4 | F2: M5 | G2: M6 | H2: M7 | I2: M8 | J2: M9 | K2: M10 | L2: M11 | M2: M12 | N2: M13 | O2: M14 | P2: M15 | Q2: M16 | R2: M17 | S2: M18 | T2: M19 | U2: M20 | V2: M21 | W2: M22 | X2: M23 | Y2: M24 | Z2: M25 | AA2: M26 | AB2: M27 | AC2: M28 | AD2: M29 | AE2: M30 | AF2: M31 | AG2: M32 | AH2: M33 | AI2: M34 | AJ2: M35 | AK2: M36
A3: Year | B3: 1 | C3: 1 | D3: 1 | E3: 1 | F3: 1 | G3: 1 | H3: 1 | I3: 1 | J3: 1 | K3: 1 | L3: 1 | M3: 1 | N3: 2 | O3: 2 | P3: 2 | Q3: 2 | R3: 2 | S3: 2 | T3: 2 | U3: 2 | V3: 2 | W3: 2 | X3: 2 | Y3: 2 | Z3: 3 | AA3: 3 | AB3: 3 | AC3: 3 | AD3: 3 | AE3: 3 | AF3: 3 | AG3: 3 | AH3: 3 | AI3: 3 | AJ3: 3 | AK3: 3
A4: Quarter | B4: Q1 | C4: Q1 | D4: Q1 | E4: Q2 | F4: Q2 | G4: Q2 | H4: Q3 | I4: Q3 | J4: Q3 | K4: Q4 | L4: Q4 | M4: Q4 | N4: Q5 | O4: Q5 | P4: Q5 | Q4: Q6 | R4: Q6 | S4: Q6 | T4: Q7 | U4: Q7 | V4: Q7 | W4: Q8 | X4: Q8 | Y4: Q8 | Z4: Q9 | AA4: Q9 | AB4: Q9 | AC4: Q10 | AD4: Q10 | AE4: Q10 | AF4: Q11 | AG4: Q11 | AH4: Q11 | AI4: Q12 | AJ4: Q12 | AK4: Q12

Sheet 30_Assumptions_Rationale
A2: Core Assumptions & Strategic Rationale
A4: A. | B4: Business Model
B5: Payments + subscription + lending
B6: Lending activated following equity raise (timing scenario-dependent).
A8: B. | B8: Customer Growth
B9: Starting customers: 2,000 (initial GTM ramp)
B10: MoM acquisition growth: 6% (early-stage scaling)
B11: Effective Assumption = Base Assumption × Scenario Multiplier
B12: Acquisition cap at 12,000/month: operational constraint realism
A14: C. | B14: Retention
B15: Monthly churn: 3.5%(mid-market fintech benchmark)
B16: Effective Assumption = Base Assumption × Scenario Multiplier
B17: Reactivation rate: 0.3% (modest win-back)
B18: Active rate: 85% (engagement realism)
A20: D. | B20: CAC
B21: Starting CAC: 110 AED
B22: Effective Assumption = Base Assumption × Scenario Multiplier
B23: MoM improvement: -0.5%
B24: Floor at 80 AED (market efficiency boundary)
A26: E. | B26: Capital Strategy
B27: Seed: 5m initial equity
B28: Raise at Month 6
B29: 4m AED venture debt facility
B30: ARR multiple: 8x (growth fintech range)
A32: F. | B32: Cost Structure
B33: Fixed brand marketing included in OPEX
B34: Capitalization only on Eng + Data payroll

Sheet 31_Inputs_UnitEconomics
A1: Payments
B2: Variable | C2: Base | D2: Effective
B3: GMV per Active Customer | C3: 900
B4: Take Rate | C4: 0.012 | D4: =C4 * INDEX('21_Scenarios'!$B$5:$D$5, MATCH('01_Dashboard'!$S$25, '21_Scenarios'!$B$1:$D$1, 0)) -> 0.012
B5: Processing Cost | C5: 0.0035
B6: Chargebacks | C6: 0.0015
A7: Card
B8: Variable | C8: Base
B9: Interchange Revenue / Active | C9: 8
B10: Subscription Attach Rate | C10: 0.18
B11: Subscription Price | C11: 25
A12: Lending
B13: Variable | C13: Base
B14: Lending Penetration (annual %) | C14: 0.06
B15: Avg Principal | C15: 1800
B16: Origination Fee | C16: 0.03
B17: Monthly Yield on Outstanding | C17: 0.011
B18: Raise Month | C18: 9 | D18: =C18 + INDEX('21_Scenarios'!$B$6:$D$6, MATCH('01_Dashboard'!$S$25, '21_Scenarios'!$B$1:$D$1, 0)) -> 9
B19: Repayment Rate | C19: =1/12 -> 0.083333333
A20: Platform Serving Costs
B21: Variable | C21: Base
B22: Variable Support Cost per Active Customer (monthly) | C22: 1.2

Sheet 32_Inputs_GrowthRetention
A1: Acquisition
B2: Variable | C2: Base | D2: Effective
B3: Starting Customers | C3: 0
B4: New Customers Month 1 | C4: 2000
B5: MoM Acquisition Growth | C5: 0.06 | D5: =C5 * INDEX('21_Scenarios'!$B$2:$D$2, MATCH('01_Dashboard'!$S$25, '21_Scenarios'!$B$1:$D$1, 0)) -> 0.06
B6: Acquisition Cap | C6: 12000
A7: Retention
B8: Variable | C8: Base | D8: Effective
B9: Monthly Churn | C9: 0.035 | D9: =C9 * INDEX('21_Scenarios'!$B$3:$D$3, MATCH('01_Dashboard'!$S$25, '21_Scenarios'!$B$1:$D$1, 0)) -> 0.035
B10: Annual Churn | C10: =1-((1-C9)^12) -> 0.34787964 | D10: =1-((1-D9)^12) -> 0.34787964
B11: Reactivation Rate | C11: 0.003
B12: Active Rate | C12: 0.85
A13: CAC & Marketing
B14: Variable | C14: Base | D14: Effective
B15: CAC Month 1 | C15: 110 | D15: =C15 * INDEX('21_Scenarios'!$B$4:$D$4, MATCH('01_Dashboard'!$S$25, '21_Scenarios'!$B$1:$D$1, 0)) -> 110
B16: CAC MoM Change | C16: -0.005
B17: CAC Floor | C17: 80
B18: Fixed Brand Marketing | C18: 120000

Sheet 33_Inputs_Opex_Headcount
A1: Headcount & Payroll
B2: Function | C2: Month 1 HC | D2: Salary | E2: Weighted Salary
B3: Engineering | C3: 12 | D3: 26000 | E3: =D3*C3 -> 312000
B4: Data | C4: 3 | D4: 22000 | E4: =D4*C4 -> 66000
B5: Sales | C5: 5 | D5: 18000 | E5: =D5*C5 -> 90000
B6: CX | C6: 4 | D6: 12000 | E6: =D6*C6 -> 48000
B7: G&A | C7: 4 | D7: 20000 | E7: =D7*C7 -> 80000 | G7: Benefits Load | I7: Eng. + Data payroll %
C8: =SUM(C3:C7) -> 28 | D8: =E8/C8 -> 21285.714 | E8: =SUM(E3:E7) -> 596000 | G8: 0.15 | I8: =SUM(E3:E4)/E8 -> 0.63422819
D9: (Weighted Average Salary)
A12: Hiring Plan
A13: {='23_Time'!A2:AK2} -> Month Label | B13: M1 | C13: M2 | D13: M3 | E13: M4 | F13: M5 | G13: M6 | H13: M7 | I13: M8 | J13: M9 | K13: M10 | L13: M11 | M13: M12 | N13: M13 | O13: M14 | P13: M15 | Q13: M16 | R13: M17 | S13: M18 | T13: M19 | U13: M20 | V13: M21 | W13: M22 | X13: M23 | Y13: M24 | Z13: M25 | AA13: M26 | AB13: M27 | AC13: M28 | AD13: M29 | AE13: M30 | AF13: M31 | AG13: M32 | AH13: M33 | AI13: M34 | AJ13: M35 | AK13: M36
A14: Hires | B14: 0 | C14: =IF('23_Time'!C3 = 1,2,1) -> 2 | D14: =IF('23_Time'!D3 = 1,2,1) -> 2 | E14: =IF('23_Time'!E3 = 1,2,1) -> 2 | F14: =IF('23_Time'!F3 = 1,2,1) -> 2 | G14: =IF('23_Time'!G3 = 1,2,1) -> 2 | H14: =IF('23_Time'!H3 = 1,2,1) -> 2 | I14: =IF('23_Time'!I3 = 1,2,1) -> 2 | J14: =IF('23_Time'!J3 = 1,2,1) -> 2 | ... AK14: =IF('23_Time'!AK3 = 1,2,1) -> 1

Sheet 34_Inputs_Opex_NonPeople
G1: Variable | H1: Base
G2: Cloud & SaaS | H2: 150000
G3: Rent | H3: 60000
G4: Legal/Audit | H4: 25000
G5: G&A Misc | H5: 35000
G6: R&D Non-People | H6: 40000
G7: Total | H7: =SUM(H2:H6) -> 310000

Sheet 35_Inputs_Capex_WC
A1: Variable | B1: Base
A2: Capitalized Software % of Eng+Data Payroll | B2: 0.08
A3: Other Capex Monthly | B3: 25000
A4: Depreciation Life (Years) | B4: 3
A5: Monthly Depreciation | B5: =1/36 -> 0.027777778
A6: AR Days | B6: 12
A7: AP Days | B7: 25
A8: Subscription Deferred Months | B8: 1

Sheet 36_Inputs_Funding
A1: Variable | B1: Base
A2: Starting Cash | B2: 5000000
A3: Equity Raise Month | B3: ='21_Scenarios'!G2 -> 6
A4: Equity Raise Amount | B4: ='21_Scenarios'!H2 -> 25000000
A5: Debt Facility | B5: 4000000
A6: Debt Draw Month 1 | B6: 6
A7: Debt Draw Amount 1 | B7: 1000000
A8: Debt Draw Month 2 | B8: 9
A9: Debt Draw Amount 2 | B9: 1000000
A10: Interest Rate | B10: 0.1

Sheet 37_Inputs_Tax
A1: Variable | B1: Base
A2: Corporate Tax Rate | B2: 0.09

Sheet 40_Customers_Orders
A1: {='23_Time'!A1:AK2} -> Month Index | B1: 1 | C1: 2 | D1: 3 | E1: 4 | F1: 5 | G1: 6 | H1: 7 | I1: 8 | J1: 9 | K1: 10 | L1: 11 | M1: 12 | N1: 13 | O1: 14 | P1: 15 | Q1: 16 | R1: 17 | S1: 18 | T1: 19 | U1: 20 | V1: 21 | W1: 22 | X1: 23 | Y1: 24 | Z1: 25 | AA1: 26 | AB1: 27 | AC1: 28 | AD1: 29 | AE1: 30 | AF1: 31 | AG1: 32 | AH1: 33 | AI1: 34 | AJ1: 35 | AK1: 36
A2: Month Label | B2: M1 | C2: M2 | D2: M3 | E2: M4 | F2: M5 | G2: M6 | H2: M7 | I2: M8 | J2: M9 | K2: M10 | L2: M11 | M2: M12 | N2: M13 | O2: M14 | P2: M15 | Q2: M16 | R2: M17 | S2: M18 | T2: M19 | U2: M20 | V2: M21 | W2: M22 | X2: M23 | Y2: M24 | Z2: M25 | AA2: M26 | AB2: M27 | AC2: M28 | AD2: M29 | AE2: M30 | AF2: M31 | AG2: M32 | AH2: M33 | AI2: M34 | AJ2: M35 | AK2: M36 | AL2: Y1 Total | AM2: Y2 Total | AN2: Y3 Total
A3: Beginning Customers | B3: ='32_Inputs_GrowthRetention'!C3 -> 0 | C3: =B7 -> 2000 | D3: =C7 -> 4050.21 | E3: =D7 -> 6156.0779 | F3: =E7 -> 8323.2936 | G3: =F7 -> 10557.806 | H3: =G7 -> 12865.843 | I3: =H7 -> 15253.927 | J3: =I7 -> 17728.902 | ... AK3: =AJ7 -> 150783.95 | AL3: =B3 -> 0 | AM3: =N3 -> 28646.907 | AN3: =Z3 -> 76348.844
A4: New Customers | B4: ='32_Inputs_GrowthRetention'!C4 -> 2000 | C4: =MIN(B4*(1 + '32_Inputs_GrowthRetention'!$D$5),'32_Inputs_GrowthRetention'!$C$6) -> 2120 | D4: =MIN(C4*(1 + '32_Inputs_GrowthRetention'!$D$5),'32_Inputs_GrowthRetention'!$C$6) -> 2247.2 | E4: =MIN(D4*(1 + '32_Inputs_GrowthRetention'!$D$5),'32_Inputs_GrowthRetention'!$C$6) -> 2382.032 | F4: =MIN(E4*(1 + '32_Inputs_GrowthRetention'!$D$5),'32_Inputs_GrowthRetention'!$C$6) -> 2524.9539 | G4: =MIN(F4*(1 + '32_Inputs_GrowthRetention'!$D$5),'32_Inputs_GrowthRetention'!$C$6) -> 2676.4512 | H4: =MIN(G4*(1 + '32_Inputs_GrowthRetention'!$D$5),'32_Inputs_GrowthRetention'!$C$6) -> 2837.0382 | I4: =MIN(H4*(1 + '32_Inputs_GrowthRetention'!$D$5),'32_Inputs_GrowthRetention'!$C$6) -> 3007.2605 | J4: =MIN(I4*(1 + '32_Inputs_GrowthRetention'!$D$5),'32_Inputs_GrowthRetention'!$C$6) -> 3187.6961 | ... AK4: =MIN(AJ4*(1 + '32_Inputs_GrowthRetention'!$D$5),'32_Inputs_GrowthRetention'!$C$6) -> 12000 | AL4: =SUMIF('23_Time'!$B$3:$AK$3, 1,B4:AK4) -> 33739.882 | AM4: =SUMIF('23_Time'!$B$3:$AK$3, 2,B4:AK4) -> 67891.272 | AN4: =SUMIF('23_Time'!$B$3:$AK$3, 3,B4:AK4) -> 127972.2
A5: Churned Customers | B5: =B3*'32_Inputs_GrowthRetention'!$D$9 -> 0 | C5: =C3*'32_Inputs_GrowthRetention'!$D$9 -> 70 | D5: =D3*'32_Inputs_GrowthRetention'!$D$9 -> 141.75735 | E5: =E3*'32_Inputs_GrowthRetention'!$D$9 -> 215.46273 | F5: =F3*'32_Inputs_GrowthRetention'!$D$9 -> 291.31528 | G5: =G3*'32_Inputs_GrowthRetention'!$D$9 -> 369.52322 | H5: =H3*'32_Inputs_GrowthRetention'!$D$9 -> 450.30449 | I5: =I3*'32_Inputs_GrowthRetention'!$D$9 -> 533.88746 | ... AK5: =AK3*'32_Inputs_GrowthRetention'!$D$9 -> 5277.4381 | AL5: =SUMIF('23_Time'!$B$3:$AK$3, 1,B5:AK5) -> 5108.3001 | AM5: =SUMIF('23_Time'!$B$3:$AK$3, 2,B5:AK5) -> 20250.086 | AN5: =SUMIF('23_Time'!$B$3:$AK$3, 3,B5:AK5) -> 46939.523
A6: Reactivated Customers | B6: =B5*'32_Inputs_GrowthRetention'!$C$11 -> 0 | C6: =C5*'32_Inputs_GrowthRetention'!$C$11 -> 0.21 | D6: =D5*'32_Inputs_GrowthRetention'!$C$11 -> 0.42527205 | E6: =E5*'32_Inputs_GrowthRetention'!$C$11 -> 0.64638818 | F6: =F5*'32_Inputs_GrowthRetention'!$C$11 -> 0.87394583 | G6: =G5*'32_Inputs_GrowthRetention'!$C$11 -> 1.1085696 | H6: =H5*'32_Inputs_GrowthRetention'!$C$11 -> 1.3509135 | I6: =I5*'32_Inputs_GrowthRetention'!$C$11 -> 1.6016624 | ... AK6: =AK5*'32_Inputs_GrowthRetention'!$C$11 -> 15.832314 | AL6: =SUMIF('23_Time'!$B$3:$AK$3, 1,B6:AK6) -> 15.3249 | AM6: =SUMIF('23_Time'!$B$3:$AK$3, 2,B6:AK6) -> 60.750258 | AN6: =SUMIF('23_Time'!$B$3:$AK$3, 3,B6:AK6) -> 140.81857
A7: Ending Customers | B7: =B3+B4-B5+B6 -> 2000 | C7: =C3+C4-C5+C6 -> 4050.21 | D7: =D3+D4-D5+D6 -> 6156.0779 | E7: =E3+E4-E5+E6 -> 8323.2936 | F7: =F3+F4-F5+F6 -> 10557.806 | G7: =G3+G4-G5+G6 -> 12865.843 | H7: =H3+H4-H5+H6 -> 15253.927 | I7: =I3+I4-I5+I6 -> 17728.902 | ... AK7: =AK3+AK4-AK5+AK6 -> 157522.34 | AL7: =M7 -> 28646.907 | AM7: =Y7 -> 76348.844 | AN7: =AK7 -> 157522.34
A8: Active Customers | B8: =B7*'32_Inputs_GrowthRetention'!$C$12 -> 1700 | C8: =C7*'32_Inputs_GrowthRetention'!$C$12 -> 3442.6785 | D8: =D7*'32_Inputs_GrowthRetention'!$C$12 -> 5232.6662 | E8: =E7*'32_Inputs_GrowthRetention'!$C$12 -> 7074.7995 | F8: =F7*'32_Inputs_GrowthRetention'!$C$12 -> 8974.1352 | G8: =G7*'32_Inputs_GrowthRetention'!$C$12 -> 10935.966 | H8: =H7*'32_Inputs_GrowthRetention'!$C$12 -> 12965.838 | I8: =I7*'32_Inputs_GrowthRetention'!$C$12 -> 15069.567 | ... AN8: =AN7*'32_Inputs_GrowthRetention'!$C$12 -> 133893.99
A9: Net Customer Growth | B9: =B7-B3 -> 2000 | C9: =C7-C3 -> 2050.21 | D9: =D7-D3 -> 2105.8679 | E9: =E7-E3 -> 2167.2157 | F9: =F7-F3 -> 2234.5126 | G9: =G7-G3 -> 2308.0365 | H9: =H7-H3 -> 2388.0846 | I9: =I7-I3 -> 2474.9747 | ... AK9: =AK7-AK3 -> 6738.3942 | AL9: =SUMIF('23_Time'!$B$3:$AK$3, 1,B9:AK9) -> 28646.907 | AM9: =SUMIF('23_Time'!$B$3:$AK$3, 2,B9:AK9) -> 47701.936 | AN9: =SUMIF('23_Time'!$B$3:$AK$3, 3,B9:AK9) -> 81173.496

Sheet 41_Revenue_COGS
A1: {='23_Time'!A1:AK2} -> Month Index | B1: 1 | C1: 2 | D1: 3 | E1: 4 | F1: 5 | G1: 6 | H1: 7 | I1: 8 | J1: 9 | K1: 10 | L1: 11 | M1: 12 | N1: 13 | O1: 14 | P1: 15 | Q1: 16 | R1: 17 | S1: 18 | T1: 19 | U1: 20 | V1: 21 | W1: 22 | X1: 23 | Y1: 24 | Z1: 25 | AA1: 26 | AB1: 27 | AC1: 28 | AD1: 29 | AE1: 30 | AF1: 31 | AG1: 32 | AH1: 33 | AI1: 34 | AJ1: 35 | AK1: 36
A2: Month Label | B2: M1 | C2: M2 | D2: M3 | E2: M4 | F2: M5 | G2: M6 | H2: M7 | I2: M8 | J2: M9 | K2: M10 | L2: M11 | M2: M12 | N2: M13 | O2: M14 | P2: M15 | Q2: M16 | R2: M17 | S2: M18 | T2: M19 | U2: M20 | V2: M21 | W2: M22 | X2: M23 | Y2: M24 | Z2: M25 | AA2: M26 | AB2: M27 | AC2: M28 | AD2: M29 | AE2: M30 | AF2: M31 | AG2: M32 | AH2: M33 | AI2: M34 | AJ2: M35 | AK2: M36 | AL2: Y1 Total | AM2: Y2 Total | AN2: Y3 Total
A3: GMV | B3: ='40_Customers_Orders'!B8*'31_Inputs_UnitEconomics'!$C$3 -> 1530000 | C3: ='40_Customers_Orders'!C8*'31_Inputs_UnitEconomics'!$C$3 -> 3098410.6 | D3: ='40_Customers_Orders'!D8*'31_Inputs_UnitEconomics'!$C$3 -> 4709399.6 | E3: ='40_Customers_Orders'!E8*'31_Inputs_UnitEconomics'!$C$3 -> 6367319.6 | F3: ='40_Customers_Orders'!F8*'31_Inputs_UnitEconomics'!$C$3 -> 8076721.7 | G3: ='40_Customers_Orders'!G8*'31_Inputs_UnitEconomics'!$C$3 -> 9842369.7 | H3: ='40_Customers_Orders'!H8*'31_Inputs_UnitEconomics'!$C$3 -> 11669254 | I3: ='40_Customers_Orders'!I8*'31_Inputs_UnitEconomics'!$C$3 -> 13562610 | ... AK3: ='40_Customers_Orders'!AK8*'31_Inputs_UnitEconomics'!$C$3 -> 1.2050459e+08 | AL3: =SUMIF('23_Time'!$B$3:$AK$3, 1,$B$3:$AK$3) -> 1.3356773e+08 | AM3: =SUMIF('23_Time'!$B$3:$AK$3, 2,$B$3:$AK$3) -> 4.7910101e+08 | AN3: =SUMIF('23_Time'!$B$3:$AK$3, 3,$B$3:$AK$3) -> 1.0880616e+09
A4: Payments Revenue | B4: =B3*'31_Inputs_UnitEconomics'!$D$4 -> 18360 | C4: =C3*'31_Inputs_UnitEconomics'!$D$4 -> 37180.928 | D4: =D3*'31_Inputs_UnitEconomics'!$D$4 -> 56512.795 | E4: =E3*'31_Inputs_UnitEconomics'!$D$4 -> 76407.835 | F4: =F3*'31_Inputs_UnitEconomics'!$D$4 -> 96920.661 | G4: =G3*'31_Inputs_UnitEconomics'!$D$4 -> 118108.44 | H4: =H3*'31_Inputs_UnitEconomics'!$D$4 -> 140031.05 | I4: =I3*'31_Inputs_UnitEconomics'!$D$4 -> 162751.32 | ... AK4: =AK3*'31_Inputs_UnitEconomics'!$D$4 -> 1446055.1 | AL4: =SUMIF('23_Time'!$B$3:$AK$3, 1,$B$4:$AK$4) -> 1602812.8 | AM4: =SUMIF('23_Time'!$B$3:$AK$3, 2,$B$4:$AK$4) -> 5749212.1 | AN4: =SUMIF('23_Time'!$B$3:$AK$3, 3,$B$4:$AK$4) -> 13056739
A5: Processing Cost | B5: =B3*'31_Inputs_UnitEconomics'!$C$5 -> 5355 | C5: =C3*'31_Inputs_UnitEconomics'!$C$5 -> 10844.437 | D5: =D3*'31_Inputs_UnitEconomics'!$C$5 -> 16482.899 | E5: =E3*'31_Inputs_UnitEconomics'!$C$5 -> 22285.619 | F5: =F3*'31_Inputs_UnitEconomics'!$C$5 -> 28268.526 | G5: =G3*'31_Inputs_UnitEconomics'!$C$5 -> 34448.294 | H5: =H3*'31_Inputs_UnitEconomics'!$C$5 -> 40842.39 | I5: =I3*'31_Inputs_UnitEconomics'!$C$5 -> 47469.135 | ... AK5: =AK3*'31_Inputs_UnitEconomics'!$C$5 -> 421766.06 | AL5: =SUMIF('23_Time'!$B$3:$AK$3, 1,$B$5:$AK$5) -> 467487.05 | AM5: =SUMIF('23_Time'!$B$3:$AK$3, 2,$B$5:$AK$5) -> 1676853.5 | AN5: =SUMIF('23_Time'!$B$3:$AK$3, 3,$B$5:$AK$5) -> 3808215.5
A6: Chargebacks | B6: =B3*'31_Inputs_UnitEconomics'!$C$6 -> 2295 | C6: =C3*'31_Inputs_UnitEconomics'!$C$6 -> 4647.616 | D6: =D3*'31_Inputs_UnitEconomics'!$C$6 -> 7064.0994 | E6: =E3*'31_Inputs_UnitEconomics'!$C$6 -> 9550.9794 | F6: =F3*'31_Inputs_UnitEconomics'!$C$6 -> 12115.083 | G6: =G3*'31_Inputs_UnitEconomics'!$C$6 -> 14763.554 | H6: =H3*'31_Inputs_UnitEconomics'!$C$6 -> 17503.882 | I6: =I3*'31_Inputs_UnitEconomics'!$C$6 -> 20343.915 | ... AK6: =AK3*'31_Inputs_UnitEconomics'!$C$6 -> 180756.88 | AL6: =SUMIF('23_Time'!$B$3:$AK$3, 1,$B$6:$AK$6) -> 200351.59 | AM6: =SUMIF('23_Time'!$B$3:$AK$3, 2,$B$6:$AK$6) -> 718651.51 | AN6: =SUMIF('23_Time'!$B$3:$AK$3, 3,$B$6:$AK$6) -> 1632092.4
A7: Payments Gross Profit | B7: =B4-B5-B6 -> 10710 | C7: =C4-C5-C6 -> 21688.875 | D7: =D4-D5-D6 -> 32965.797 | E7: =E4-E5-E6 -> 44571.237 | F7: =F4-F5-F6 -> 56537.052 | G7: =G4-G5-G6 -> 68896.588 | H7: =H4-H5-H6 -> 81684.781 | I7: =I4-I5-I6 -> 94938.27 | ... AK7: =AK4-AK5-AK6 -> 843532.13 | AL7: =SUMIF('23_Time'!$B$3:$AK$3, 1,B7:AK7) -> 934974.11 | AM7: =SUMIF('23_Time'!$B$3:$AK$3, 2,B7:AK7) -> 3353707 | AN7: =SUMIF('23_Time'!$B$3:$AK$3, 3,B7:AK7) -> 7616431.1
A8: Card Interchange Revenue | B8: ='40_Customers_Orders'!B8*'31_Inputs_UnitEconomics'!$C$9 -> 13600 | C8: ='40_Customers_Orders'!C8*'31_Inputs_UnitEconomics'!$C$9 -> 27541.428 | D8: ='40_Customers_Orders'!D8*'31_Inputs_UnitEconomics'!$C$9 -> 41861.33 | E8: ='40_Customers_Orders'!E8*'31_Inputs_UnitEconomics'!$C$9 -> 56598.396 | F8: ='40_Customers_Orders'!F8*'31_Inputs_UnitEconomics'!$C$9 -> 71793.082 | G8: ='40_Customers_Orders'!G8*'31_Inputs_UnitEconomics'!$C$9 -> 87487.73 | H8: ='40_Customers_Orders'!H8*'31_Inputs_UnitEconomics'!$C$9 -> 103726.71 | I8: ='40_Customers_Orders'!I8*'31_Inputs_UnitEconomics'!$C$9 -> 120556.53 | ... AK8: ='40_Customers_Orders'!AK8*'31_Inputs_UnitEconomics'!$C$9 -> 1071151.9 | AL8: =SUMIF('23_Time'!$B$3:$AK$3, 1,B8:AK8) -> 1187268.7 | AM8: =SUMIF('23_Time'!$B$3:$AK$3, 2,B8:AK8) -> 4258675.6 | AN8: =SUMIF('23_Time'!$B$3:$AK$3, 3,B8:AK8) -> 9671658.5
A9: Subscribed Users | B9: ='40_Customers_Orders'!B8*'31_Inputs_UnitEconomics'!$C$10 -> 306 | C9: ='40_Customers_Orders'!C8*'31_Inputs_UnitEconomics'!$C$10 -> 619.68213 | D9: ='40_Customers_Orders'!D8*'31_Inputs_UnitEconomics'!$C$10 -> 941.87992 | E9: ='40_Customers_Orders'!E8*'31_Inputs_UnitEconomics'!$C$10 -> 1273.4639 | F9: ='40_Customers_Orders'!F8*'31_Inputs_UnitEconomics'!$C$10 -> 1615.3443 | G9: ='40_Customers_Orders'!G8*'31_Inputs_UnitEconomics'!$C$10 -> 1968.4739 | H9: ='40_Customers_Orders'!H8*'31_Inputs_UnitEconomics'!$C$10 -> 2333.8509 | I9: ='40_Customers_Orders'!I8*'31_Inputs_UnitEconomics'!$C$10 -> 2712.522 | ... AK9: ='40_Customers_Orders'!AK8*'31_Inputs_UnitEconomics'!$C$10 -> 24100.918 | AL9: =SUMIF('23_Time'!$B$3:$AK$3, 1,B9:AK9) -> 26713.546 | AM9: =SUMIF('23_Time'!$B$3:$AK$3, 2,B9:AK9) -> 95820.201 | AN9: =SUMIF('23_Time'!$B$3:$AK$3, 3,B9:AK9) -> 217612.32
A10: Subscription Revenue | B10: =B9*'31_Inputs_UnitEconomics'!$C$11 -> 7650 | C10: =C9*'31_Inputs_UnitEconomics'!$C$11 -> 15492.053 | D10: =D9*'31_Inputs_UnitEconomics'!$C$11 -> 23546.998 | E10: =E9*'31_Inputs_UnitEconomics'!$C$11 -> 31836.598 | F10: =F9*'31_Inputs_UnitEconomics'!$C$11 -> 40383.609 | G10: =G9*'31_Inputs_UnitEconomics'!$C$11 -> 49211.848 | H10: =H9*'31_Inputs_UnitEconomics'!$C$11 -> 58346.272 | I10: =I9*'31_Inputs_UnitEconomics'!$C$11 -> 67813.05 | ... AK10: =AK9*'31_Inputs_UnitEconomics'!$C$11 -> 602522.95 | AL10: =SUMIF('23_Time'!$B$3:$AK$3, 1,B10:AK10) -> 667838.65 | AM10: =SUMIF('23_Time'!$B$3:$AK$3, 2,B10:AK10) -> 2395505 | AN10: =SUMIF('23_Time'!$B$3:$AK$3, 3,B10:AK10) -> 5440307.9
A11: Card Total Revenue | B11: =B8+B10 -> 21250 | C11: =C8+C10 -> 43033.481 | D11: =D8+D10 -> 65408.328 | E11: =E8+E10 -> 88434.994 | F11: =F8+F10 -> 112176.69 | G11: =G8+G10 -> 136699.58 | H11: =H8+H10 -> 162072.98 | I11: =I8+I10 -> 188369.58 | ... AK11: =AK8+AK10 -> 1673674.9 | AL11: =SUMIF('23_Time'!$B$3:$AK$3, 1,B11:AK11) -> 1855107.4 | AM11: =SUMIF('23_Time'!$B$3:$AK$3, 2,B11:AK11) -> 6654180.6 | AN11: =SUMIF('23_Time'!$B$3:$AK$3, 3,B11:AK11) -> 15111966
A12: Lending Active Flag | B12: =IF( '23_Time'!B1>= '31_Inputs_UnitEconomics'!$D$18, 1, 0 ) -> 0 | C12: =IF( '23_Time'!C1>= '31_Inputs_UnitEconomics'!$D$18, 1, 0 ) -> 0 | D12: =IF( '23_Time'!D1>= '31_Inputs_UnitEconomics'!$D$18, 1, 0 ) -> 0 | E12: =IF( '23_Time'!E1>= '31_Inputs_UnitEconomics'!$D$18, 1, 0 ) -> 0 | F12: =IF( '23_Time'!F1>= '31_Inputs_UnitEconomics'!$D$18, 1, 0 ) -> 0 | G12: =IF( '23_Time'!G1>= '31_Inputs_UnitEconomics'!$D$18, 1, 0 ) -> 0 | H12: =IF( '23_Time'!H1>= '31_Inputs_UnitEconomics'!$D$18, 1, 0 ) -> 0 | I12: =IF( '23_Time'!I1>= '31_Inputs_UnitEconomics'!$D$18, 1, 0 ) -> 0 | ... AK12: =IF( '23_Time'!AK1>= '31_Inputs_UnitEconomics'!$D$18, 1, 0 ) -> 1
A13: Monthly Penetration | B13: ='31_Inputs_UnitEconomics'!$C$14/12 -> 0.005 | C13: ='31_Inputs_UnitEconomics'!$C$14/12 -> 0.005 | D13: ='31_Inputs_UnitEconomics'!$C$14/12 -> 0.005 | E13: ='31_Inputs_UnitEconomics'!$C$14/12 -> 0.005 | F13: ='31_Inputs_UnitEconomics'!$C$14/12 -> 0.005 | G13: ='31_Inputs_UnitEconomics'!$C$14/12 -> 0.005 | H13: ='31_Inputs_UnitEconomics'!$C$14/12 -> 0.005 | I13: ='31_Inputs_UnitEconomics'!$C$14/12 -> 0.005 | ... AK13: ='31_Inputs_UnitEconomics'!$C$14/12 -> 0.005
A14: New Loans Issued | B14: =B13*B12*'40_Customers_Orders'!B8 -> 0 | C14: =C13*C12*'40_Customers_Orders'!C8 -> 0 | D14: =D13*D12*'40_Customers_Orders'!D8 -> 0 | E14: =E13*E12*'40_Customers_Orders'!E8 -> 0 | F14: =F13*F12*'40_Customers_Orders'!F8 -> 0 | G14: =G13*G12*'40_Customers_Orders'!G8 -> 0 | H14: =H13*H12*'40_Customers_Orders'!H8 -> 0 | I14: =I13*I12*'40_Customers_Orders'!I8 -> 0 | ... AK14: =AK13*AK12*'40_Customers_Orders'!AK8 -> 669.46994 | AL14: =SUMIF('23_Time'!$B$3:$AK$3, 1,B14:AK14) -> 415.06469 | AM14: =SUMIF('23_Time'!$B$3:$AK$3, 2,B14:AK14) -> 2661.6723 | AN14: =SUMIF('23_Time'!$B$3:$AK$3, 3,B14:AK14) -> 6044.7866
